Workbook

Sheet GRADE 10 2026
A2: KIREMBE SECONDARY SCHOOL.
A3: REMEDIAL PAYMENTS GRADE 10 | I3: 1ST TERM | L3: 2ND TERM | P3: 3RD TERM
A4: NO. | C4: NAME | E4: DEBT | H4: REPAYMENT
D5: ARREAS | E5: 2026 | H5: JAN | I5: FEB | J5: MAR | K5: APR | L5: MAY | M5: JUN | N5: JUL | O5: AUG | P5: SEP | Q5: OCT | R5: NOV | S5: PRE PAID | T5: BALANCE
A6: 01 | B6: 1862 | C6: MODESTER ATIENO | E6: 2200 | P6: 1200 | T6: =D6+SUM(E6:F6)-SUM(H6:S6)
A7: 02 | B7: 1863 | C7: OWILA DORCUS | E7: 2200 | H7: 800 | L7: 500 | T7: =D7+SUM(E7:G7)-SUM(H7:S7)
A8: 03 | B8: 1865 | C8: NANCY AWINO | E8: 2200 | H8: 300 | T8: =D8+SUM(E8:G8)-SUM(H8:S8)
A9: 04 | B9: 1866 | C9: BLESSING WISHENGA | E9: 2200 | H9: 800 | N9: 1600 | T9: =D9+SUM(E9:G9)-SUM(H9:S9)
A10: 05 | B10: 1867 | C10: FAITH OWUOR | E10: 2200 | H10: 800 | T10: =D10+SUM(E10:G10)-SUM(H10:S10)
A11: 06 | B11: 1868 | C11: VALLARY AKOTH | E11: 2200 | H11: 800 | M11: 1300 | T11: =D11+SUM(E11:G11)-SUM(H11:S11)
A12: 07 | B12: 1871 | C12: MICHEL AKINYI | E12: 2200 | H12: 300 | N12: 500 | T12: =D12+SUM(E12:G12)-SUM(H12:S12)
A13: 08 | B13: 1875 | C13: GLORIA AKINYI | E13: 2200 | H13: 800 | T13: =D13+SUM(E13:G13)-SUM(H13:S13)
A14: 09 | B14: 1878 | C14: MIRIAM ATIENO | E14: 2200 | T14: =D14+SUM(E14:F14)-SUM(H14:S14)
A15: 10 | B15: 1880 | C15: MARY ATIENO | E15: 2200 | H15: 500 | N15: 1000 | T15: =D15+SUM(E15:F15)-SUM(H15:S15)
A16: 11 | B16: 1882 | C16: SHIVEL ACHIENG | E16: 2200 | T16: =D16+SUM(E16:G16)-SUM(H16:S16)
A17: 12 | B17: 1881 | C17: SILVIA AKINYI | E17: 2200 | H17: 800 | T17: =D17+SUM(E17:G17)-SUM(H17:S17)
A18: 13 | B18: 1886 | C18: ROSEMARY AWUOR | E18: 2200 | H18: 800 | T18: =D18+SUM(E18:G18)-SUM(H18:S18)
A19: 14 | B19: 1893 | C19: HANA ANYANGO | E19: 2200 | H19: 800 | T19: =D19+SUM(E19:G19)-SUM(H19:S19)
A20: 15 | B20: 1889 | C20: NICKOLE VALL | E20: 2200 | H20: 800 | T20: =D20+SUM(E20:G20)-SUM(H20:S20)
A21: 16 | B21: 1895 | C21: LAURINE ACHIENG | E21: 2200 | H21: 800 | T21: =D21+SUM(E21:G21)-SUM(H21:S21)
A22: 17 | B22: 1896 | C22: MACREEN CINDY | E22: 2200 | H22: 800 | M22: 1500 | T22: =D22+SUM(E22:F22)-SUM(H22:S22)
A23: 18 | B23: 1898 | C23: VELMA ANYANGO | E23: 2200 | H23: 600 | N23: 1000 | T23: =D23+SUM(E23:G23)-SUM(H23:S23)
A24: 19 | B24: 1899 | C24: SHYLLIN MORAA | E24: 2200 | H24: 0 | T24: =D24+SUM(E24:G24)-SUM(H24:S24)
A25: 20 | B25: 1903 | C25: FIONA FENNY | E25: 2200 | H25: 500 | T25: =D25+SUM(E25:G25)-SUM(H25:S25)
A26: 21 | B26: 1904 | C26: FAITH ADHIAMBO | E26: 2200 | H26: 0 | T26: =D26+SUM(E26:G26)-SUM(H26:S26)
A27: 23 | B27: 1908 | C27: MITCHEL AMONDI | E27: 2200 | T27: =D27+SUM(E27:F27)-SUM(H27:S27)
A28: 24 | B28: 1907 | C28: GRACE ADHIAMBO | E28: 2200 | H28: 800 | N28: 1100 | T28: =D28+SUM(E28:G28)-SUM(H28:S28)
A29: 25 | B29: 1909 | C29: MARY ATIENO | E29: 2200 | H29: 800 | T29: =D29+SUM(E29:G29)-SUM(H29:S29)
A30: 26 | B30: 1915 | C30: MACRINE AKINYI | E30: 2200 | H30: 800 | T30: =D30+SUM(E30:G30)-SUM(H30:S30)
A31: 27 | B31: 1916 | C31: ATIENO SHARON | E31: 2200 | H31: 400 | T31: =D31+SUM(E31:G31)-SUM(H31:S31)
C32: TOTAL | D32: =SUM(D6:D31) | E32: =SUM(E6:E31) | F32: =SUM(F6:F31) | G32: =SUM(G6:G31) | H32: =SUM(H6:H31) | I32: =SUM(I6:I31) | J32: =SUM(J6:J31) | K32: =SUM(K6:K31) | ... T32: =SUM(T6:T31)
A36: KIREMBE SECONDARY SCHOOL.
A37: REMEDIAL PAYMENTS GRADE 10 | I37: 1ST TERM | L37: 2ND TERM | P37: 3RD TERM
A38: NO. | B38: ADM | C38: NAME | E38: DEBT | H38: REPAYMENT
D39: ARREAS | E39: 2026 | H39: JAN | I39: FEB | J39: MAR | K39: APR | L39: MAY | M39: JUN | N39: JUL | O39: AUG | P39: SEP | Q39: OCT | R39: NOV | S39: PRE PAID | T39: BALANCE
B40: 1 | C40: BALANCE B/D | D40: =D32 | E40: =E32 | H40: =H32 | I40: =I32 | J40: =J32 | K40: =K32 | L40: =L32 | M40: =M32 | N40: =N32 | O40: =O32 | ... Q40: =Q32 | S40: =S32 | T40: =T32
A41: 28 | B41: 1918 | C41: VALICIA ANYANGO | E41: 2200 | H41: 500 | T41: =D41+SUM(E41:F41)-SUM(H41:S41)
A42: 29 | B42: 1920 | C42: OUMA MITCHELLE | E42: 2200 | T42: =D42+SUM(E42:G42)-SUM(H42:S42)
A43: 30 | B43: 1922 | C43: BLESSINGS ACHIENG | E43: 2200 | T43: =D43+SUM(E43:G43)-SUM(H43:S43)
A44: 31 | B44: 1923 | C44: BRENDA OTUMBA | E44: 2200 | T44: =D44+SUM(E44:G44)-SUM(H44:S44)
...

Sheet FORM 2 2025
A1: KIREMBE SECONDARY SCHOOL.
A2: REMEDIAL PAYMENT (FORM 2 A) 2025 | I2: 1ST TERM | L2: 2ND TERM | P2: 3RD TERM
A3: NO. | B3: ADM | C3: NAME | E3: DEBT | H3: REPAYMENT
D4: ARREAS | E4: 2025 | H4: JAN | I4: FEB | J4: MAR | K4: APR | L4: MAY | M4: JUN | N4: JUL | O4: AUG | P4: SEP | Q4: OCT | R4: NOV | S4: PRE PAID | T4: BALANCE
A5: 01 | B5: 1710 | C5: MARY ATIENO | E5: 2200 | H5: 2400 | T5: ='FORM 2 2025'!D5
A6: 02 | B6: 1712 | C6: ASHA LATIFA | E6: 2200 | T6: =D6+SUM(E6:G6)-SUM(H6:S6)
A7: 03 | B7: 1713 | C7: IVY AWUOR | E7: 2200 | T7: =D7+SUM(E7:G7)-SUM(H7:S7)
A8: 04 | B8: 1716 | C8: JANE AKINYI | E8: 2200 | L8: 400 | M8: 200 | T8: =D8+SUM(E8:G8)-SUM(H8:S8)
A9: 05 | B9: 1717 | C9: WILFRIDA ANYANGO | D9: 1400 | E9: 2200 | H9: 1400 | J9: 600 | T9: =D9+SUM(E9:G9)-SUM(H9:S9)
A10: 06 | B10: 1720 | C10: EFFEY IDA ACHIENG | E10: 2200 | T10: =D10+SUM(E10:G10)-SUM(H10:S10)
A11: 07 | B11: 1722 | C11: MARION ANYANGO | E11: 2200 | T11: =D11+SUM(E11:G11)-SUM(H11:S11)
A12: 08 | B12: 1727 | C12: LYDIA AWUOR | E12: 2200 | T12: =D12+SUM(E12:G12)-SUM(H12:S12)
A13: 09 | B13: 1737 | C13: STACY ACHIENG | E13: 2200 | T13: =D13+SUM(E13:G13)-SUM(H13:S13)
A14: 11 | B14: 1747 | C14: CHRISTINE ATIENO | E14: 2200 | T14: =D14+SUM(E14:G14)-SUM(H14:S14)
A15: 12 | B15: 1748 | C15: PAMELA AKINYI | E15: 2200 | T15: =D15+SUM(E15:G15)-SUM(H15:S15)
A16: 13 | B16: 1752 | C16: LAVINA INZIANI | E16: 2200 | H16: 300 | I16: 100 | J16: 500 | P16: 500 | T16: =D16+SUM(E16:G16)-SUM(H16:S16)
A17: 14 | B17: 1754 | C17: IRENE AKOTH | E17: 2200 | T17: =D17+SUM(E17:G17)-SUM(H17:S17)
A18: 15 | B18: 1756 | C18: BERYL ATIENO | E18: 2200 | T18: =D18+SUM(E18:G18)-SUM(H18:S18)
A19: 16 | B19: 1757 | C19: CHRISTINE ACHIENG | E19: 2200 | P19: 1400 | T19: =D19+SUM(E19:G19)-SUM(H19:S19)
A20: 17 | B20: 1758 | C20: SHELVIA AKINYI | E20: 2200 | M20: 200 | T20: =D20+SUM(E20:G20)-SUM(H20:S20)
A21: 18 | B21: 1766 | C21: PURITY AWUOR | E21: 2200 | H21: 200 | T21: =D21+SUM(E21:G21)-SUM(H21:S21)
A22: 19 | B22: 1767 | C22: IRENE AKINYI | E22: 2200 | L22: 500 | N22: 700 | P22: 500 | T22: =D22+SUM(E22:G22)-SUM(H22:S22)
A23: 20 | B23: 1770 | C23: IDA ACHIENG | D23: 1100 | E23: 2200 | H23: 1100 | T23: =D23+SUM(E23:G23)-SUM(H23:S23)
A24: 21 | B24: 1772 | C24: VALLARY AUMA | E24: 2200 | H24: 300 | T24: =D24+SUM(E24:G24)-SUM(H24:S24)
A25: 15 | B25: 1774 | C25: DAVINE AWUOR | E25: 2200 | T25: =D25+SUM(E25:G25)-SUM(H25:S25)
A26: 23 | B26: 1781 | C26: LOREEN ATARO | D26: 600 | E26: 2200 | H26: 600 | I26: 2000 | J26: 1000 | T26: =D26+SUM(E26:G26)-SUM(H26:S26)
A27: 24 | B27: 1783 | C27: VIOLET AKINYI AKUKU | E27: 2200 | T27: =D27+SUM(E27:G27)-SUM(H27:S27)
A28: 25 | B28: 1786 | C28: MAGRET AKINYI | E28: 2200 | T28: =D28+SUM(E28:G28)-SUM(H28:S28)
A29: 26 | B29: 1787 | C29: SUSAN ADHIAMBO | E29: 2200 | H29: 200 | J29: 200 | T29: =D29+SUM(E29:G29)-SUM(H29:S29)
A30: 27 | B30: 1789 | C30: PEREZ ATIENO | D30: 900 | E30: 3100
C31: TOTAL | D31: =SUM(D5:D30) | E31: =SUM(E5:E30) | F31: =SUM(F5:F30) | G31: =SUM(G5:G30) | H31: =SUM(H5:H30) | I31: =SUM(I5:I30) | J31: =SUM(J5:J30) | K31: =SUM(K5:K30) | ... T31: =SUM(T5:T30)
A35: KIREMBE SECONDARY SCHOOL.
A36: REMEDIAL PAYMENTS (FORM 2 A) 2025 | I36: 1ST TERM | L36: 2ND TERM | P36: 3RD TERM
A37: NO. | B37: ADM | C37: NAME | E37: DEBT | H37: REPAYMENT
D38: ARREAS | E38: 2025 | H38: JAN | I38: FEB | J38: MAR | K38: APR | L38: MAY | M38: JUN | N38: JUL | O38: AUG | P38: SEP | Q38: OCT | R38: NOV | S38: PRE PAID | T38: BALANCE
B39: 1 | C39: BALANCE B/D | D39: =D31 | E39: =E31 | H39: =H31 | I39: =I31 | J39: =J31 | K39: =K31 | L39: =L31 | M39: =M31 | N39: =N31 | O39: =O31 | ... Q39: =Q31 | S39: =S31 | T39: =T31
A40: 28 | B40: 1793 | C40: STACY ADHIAMBO | E40: 2200 | H40: 0 | T40: =D40+SUM(E40:G40)-SUM(H40:S40)
A41: 29 | B41: 1794 | C41: SCOVIAN AKINYI | E41: 2200 | H41: 0 | T41: =D41+SUM(E41:G41)-SUM(H41:S41)
A42: 30 | B42: 1797 | C42: LUDY ATIENO | E42: 2200 | H42: 0 | N42: 800 | T42: =D42+SUM(E42:G42)-SUM(H42:S42)
A43: 31 | B43: 1802 | C43: STACY .A.OTUOMA | D43: 600 | E43: 2200 | H43: 800 | I43: 800 | T43: =D43+SUM(E43:G43)-SUM(H43:S43)
...

Sheet FORM 3 2025
C1: KIREMBE SECONDARY SCHOOL.
C2: FEE REGISTER(LUNCH)2025 FORM 3 A | S2: 1ST TERM | V2: 2ND TERM | Z2: 3RD TERM
C3: NO. | D3: ADM | E3: NAME | G3: DEBT | R3: REPAYMENT
F4: ARREAS | G4: 2025 | R4: JAN | S4: FEB | T4: MAR | U4: APR | V4: MAY | W4: JUN | X4: JUL | Y4: AUG | Z4: SEP | AA4: OCT | AB4: NOV | AC4: PRE PAID | AD4: BALANCE
C5: 1 | D5: 1594 | E5: MARY ANYANGO | F5: 2000 | G5: 2200 | AD5: 4200
C6: 2 | D6: 1607 | E6: ELIZABETH ACHIENG | F6: 0 | G6: 2200 | AD6: 2200
C7: 3 | D7: 1608 | E7: MICHELLE .M.AKWARE | F7: 1000 | G7: 2200 | AD7: 3200
C8: 4 | D8: 1610 | E8: BENEDETTE AWINO | F8: 1400 | G8: 2200 | AD8: 3600
C9: 5 | D9: 1613 | E9: IDA ADHIAMBO | F9: 0 | G9: 2200 | AB9: 300 | AD9: 1900
C10: 6 | D10: 1614 | E10: MILLICENT .A. ONDU | F10: 0 | G10: 2200 | V10: 800 | X10: 150 | Z10: 600 | AD10: 650
C11: 7 | D11: 1618 | E11: YVONE ACHIENG | F11: 2000 | G11: 2200 | AD11: 4200
C12: 8 | D12: 1619 | E12: JANET ODANYA | F12: 900 | G12: 2200 | R12: 1000 | AD12: 2100
C13: 9 | D13: 1622 | E13: PAULINE ADHIAMBO | F13: 300 | G13: 2200 | X13: 800 | AD13: 1700
C14: 10 | D14: 1623 | E14: EFFIE AWINO | F14: 0 | G14: 2200 | R14: 200 | T14: 500 | V14: 650 | X14: 150 | AB14: 1500 | AD14: -800
C15: 11 | D15: 1626 | E15: MARCY ADHIAMBO | F15: 2200 | G15: 2200 | AD15: 4400
C16: 12 | D16: 1628 | E16: ANN MICHELL OCHUKA | F16: 0 | G16: 2200 | T16: 800 | V16: 800 | X16: 400 | AB16: 500 | AD16: -300
C17: 13 | D17: 1631 | E17: EVERLYNE ATIENO | F17: 1500 | G17: 2200 | V17: 200 | AD17: 3500
C18: 14 | D18: 1642 | E18: FLORENCE ATIENO | F18: 200 | G18: 2200 | R18: 100 | V18: 600 | AD18: 1700
C19: 15 | D19: 1643 | E19: JOYCE ATIENO | F19: 800 | G19: 2200 | V19: 600 | AB19: 800 | AD19: 1600
C20: 16 | D20: 1644 | E20: ANNA ATIENO OTIENO | F20: 2000 | G20: 2200 | AD20: 4200
C21: 17 | D21: 1646 | E21: JULIAN ADONGO | F21: 0 | G21: 2200 | R21: 800 | V21: 600 | AD21: 800
C22: 18 | D22: 1648 | E22: BECKY AKINYI | F22: 1650 | G22: 2200 | AD22: 3850
C23: 19 | D23: 1649 | E23: VIVIAN AYAKO | F23: 0 | G23: 2200 | V23: 1600 | AD23: 600
C24: 20 | D24: 1654 | E24: MITCHEL AUMA | F24: 1750 | G24: 2200 | X24: 500 | AD24: 3450
C25: 21 | D25: 1655 | E25: MILLICENT OCHUKA | F25: 1400 | G25: 2200 | R25: 200 | AD25: 3000
C26: 22 | D26: 1660 | E26: FAITH MARION | F26: 1050 | G26: 2200 | AD26: 3250
C27: 23 | D27: 1661 | E27: LILIAN ADONGO | F27: 950 | G27: 2200 | AD27: 3150
C28: 24 | D28: 1662 | E28: MARCELINE AWUOR | F28: 1800 | G28: 2200 | AD28: 4000
C29: 25 | D29: 1665 | E29: BRENDA AWUOR | F29: 300 | G29: 2200 | AD29: 2500
C30: 26 | D30: 1666 | E30: PAMELA AOKO | F30: 2000 | G30: 2200 | AD30: 4200
E31: TOTAL | F31: =SUM(F5:F30) | G31: =SUM(G5:G30) | H31: =SUM(H5:H23) | I31: =SUM(I5:I23) | J31: =SUM(J5:J23) | K31: =SUM(K5:K23) | L31: =SUM(L5:L23) | M31: =SUM(M5:M23) | N31: =SUM(N5:N23) | O31: =SUM(O5:O23) | ... Q31: =SUM(Q5:Q23) | R31: =SUM(R5:R30) | S31: =SUM(S5:S30) | T31: =SUM(T5:T30) | U31: =SUM(U5:U30) | V31: =SUM(V5:V30) | W31: =SUM(W5:W30) | X31: =SUM(X5:X30) | Y31: =SUM(Y5:Y30) | ... AD31: =SUM(AD5:AD30)
C33: KIREMBE SECONDARY SCHOOL.
C34: FEE REGISTER(LUNCH)2025 FORM 3A | S34: 1ST TERM | V34: 2ND TERM | Z34: 3RD TERM
C35: NO. | D35: ADM | E35: NAME | G35: DEBT | R35: REPAYMENT
F36: ARREAS | G36: 2025 | R36: JAN | S36: FEB | T36: MAR | U36: APR | V36: MAY | W36: JUN | X36: JUL | Y36: AUG | Z36: SEP | AA36: OCT | AB36: NOV | AC36: PRE PAID | AD36: BALANCE
F37: =F31 | G37: =G31 | R37: =R31 | S37: =S31 | T37: =T31 | U37: =U31 | V37: =V31 | W37: =W31 | X37: =X31 | Y37: =Y31 | Z37: =Z31 | AC37: =AC31 | AD37: =AD31
C38: 27 | D38: 1667 | E38: PHILISTER ATIENO | F38: 500 | G38: 2200 | AD38: 2700
C39: 28 | D39: 1668 | E39: REHEMA ACHIENG | F39: 1150 | G39: 2200 | T39: 300 | AD39: 3050
C40: 29 | D40: 1672 | E40: MORREL AKINYI | F40: 1900 | G40: 2200 | AD40: 4100
C41: 30 | D41: 1676 | E41: CYNTHIA WEKESA | F41: 1250 | G41: 2200 | R41: 100 | Z41: 300 | AD41: 3050
...

Sheet FORM 3 2026
A1: KIREMBE SECONDARY SCHOOL.
A2: FEE REGISTER(LUNCH)2026 FORM 3 A | I2: 1ST TERM | L2: 2ND TERM | P2: 3RD TERM
A3: NO. | B3: ADM | C3: NAME | E3: DEBT | H3: REPAYMENT
D4: ARREAS | E4: 2026 | H4: JAN | I4: FEB | J4: MAR | K4: APR | L4: MAY | M4: JUN | N4: JUL | O4: AUG | P4: SEP | Q4: OCT | R4: NOV | S4: PRE PAID | T4: BALANCE
A5: 01 | B5: 1710 | C5: MARY ATIENO | D5: ='FORM 2 2025'!T5 | E5: 2200 | I5: 2400 | T5: =D5+SUM(E5:G5)-SUM(H5:S5)
A6: 02 | B6: 1712 | C6: ASHA LATIFA | D6: ='FORM 2 2025'!T6 | E6: 2200 | H6: 100 | T6: =D6+SUM(E6:G6)-SUM(H6:S6)
A7: 03 | B7: 1713 | C7: IVY AWUOR | D7: ='FORM 2 2025'!T7 | E7: 2200 | T7: =D7+SUM(E7:G7)-SUM(H7:S7)
A8: 04 | B8: 1716 | C8: JANE AKINYI | D8: ='FORM 2 2025'!T8 | E8: 2200 | T8: =D8+SUM(E8:G8)-SUM(H8:S8)
A9: 05 | B9: 1717 | C9: WILFRIDA ANYANGO | D9: ='FORM 2 2025'!T9 | E9: 2200 | P9: 2700 | T9: =D9+SUM(E9:G9)-SUM(H9:S9)
A10: 06 | B10: 1720 | C10: EFFEY IDA ACHIENG | D10: ='FORM 2 2025'!T10 | E10: 2200 | T10: =D10+SUM(E10:G10)-SUM(H10:S10)
A11: 07 | B11: 1722 | C11: MARION ANYANGO | D11: ='FORM 2 2025'!T11 | E11: 2200 | N11: 600 | T11: =D11+SUM(E11:G11)-SUM(H11:S11)
A12: 08 | B12: 1727 | C12: LYDIA AWUOR | D12: ='FORM 2 2025'!T12 | E12: 2200 | M12: 300 | T12: =D12+SUM(E12:G12)-SUM(H12:S12)
A13: 09 | B13: 1737 | C13: STACY ACHIENG | D13: ='FORM 2 2025'!T13 | E13: 2200 | N13: 600 | T13: =D13+SUM(E13:G13)-SUM(H13:S13)
A14: 11 | B14: 1747 | C14: CHRISTINE ATIENO | D14: ='FORM 2 2025'!T14 | E14: 2200 | N14: 1200
A15: 12 | B15: 1748 | C15: PAMELA AKINYI | D15: ='FORM 2 2025'!T15 | E15: 2200 | P15: 300 | T15: =D15+SUM(E15:G15)-SUM(H15:S15)
A16: 13 | B16: 1752 | C16: LAVINA INZIANI | D16: ='FORM 2 2025'!T16 | E16: 2200 | N16: 900 | T16: =D16+SUM(E16:G16)-SUM(H16:S16)
A17: 14 | B17: 1754 | C17: IRENE AKOTH | D17: ='FORM 2 2025'!T17 | E17: 2200 | P17: 2500 | T17: =D17+SUM(E17:G17)-SUM(H17:S17)
A18: 15 | B18: 1756 | C18: BERYL ATIENO | D18: ='FORM 2 2025'!T18 | E18: 2200 | P18: 250 | T18: =D18+SUM(E18:G18)-SUM(H18:S18)
A19: 16 | B19: 1757 | C19: CHRISTINE ACHIENG | D19: ='FORM 2 2025'!T19 | E19: 2200 | H19: 1000 | L19: 1800 | T19: =D19+SUM(E19:G19)-SUM(H19:S19)
A20: 17 | B20: 1758 | C20: SHELVIA AKINYI | D20: ='FORM 2 2025'!T20 | E20: 2200 | M20: 500 | T20: =D20+SUM(E20:G20)-SUM(H20:S20)
A21: 18 | B21: 1766 | C21: PURITY AWUOR | D21: ='FORM 2 2025'!T21 | E21: 2200 | T21: =D21+SUM(E21:F21)-SUM(H21:S21)
A22: 19 | B22: 1767 | C22: IRENE AKINYI | D22: ='FORM 2 2025'!T22 | E22: 2200 | H22: 800 | T22: =D22+SUM(E22:G22)-SUM(H22:S22)
A23: 20 | B23: 1770 | C23: IDA ACHIENG | D23: ='FORM 2 2025'!T23 | E23: 2200 | H23: 600 | T23: =D23+SUM(E23:G23)-SUM(H23:S23)
A24: 21 | B24: 1772 | C24: VALLARY AUMA | D24: ='FORM 2 2025'!T24 | E24: 2200 | H24: 300
A25: 15 | B25: 1774 | C25: DAVINE AWUOR | D25: ='FORM 2 2025'!T25 | E25: 2200 | T25: =D25+SUM(E25:G25)-SUM(H25:S25)
A26: 23 | B26: 1781 | C26: LOREEN ATARO | D26: ='FORM 2 2025'!T26 | E26: 2200 | H26: 800 | I26: 500 | T26: =D26+SUM(E26:G26)-SUM(H26:S26)
A27: 24 | B27: 1783 | C27: VIOLET AKINYI AKUKU | D27: ='FORM 2 2025'!T27 | E27: 2200 | H27: 100 | I27: 100 | T27: =D27+SUM(E27:G27)-SUM(H27:S27)
A28: 25 | B28: 1786 | C28: MAGRET AKINYI | D28: ='FORM 2 2025'!T28 | E28: 2200 | H28: 200 | T28: =D28+SUM(E28:G28)-SUM(H28:S28)
A29: 26 | B29: 1787 | C29: SUSAN ADHIAMBO | D29: ='FORM 2 2025'!T29 | E29: 2200 | T29: =D29+SUM(E29:G29)-SUM(H29:S29)
A30: 27 | B30: 1789 | C30: PEREZ ATIENO | D30: ='FORM 2 2025'!T30 | E30: 2200 | H30: 200 | T30: =D30+SUM(E30:G30)-SUM(H30:S30)
C31: TOTAL | D31: =SUM(D5:D30) | E31: =SUM(E1:E27) | F31: =SUM(F5:F30) | G31: =SUM(G5:G30) | H31: =SUM(H5:H30) | I31: =SUM(I5:I30) | J31: =SUM(J5:J30) | K31: =SUM(K5:K30) | L31: =SUM(L5:L30) | M31: =SUM(M5:M30) | ... T31: =SUM(T5:T30)
A35: KIREMBE SECONDARY SCHOOL.
A36: REMEDIAL PAYMENTS (FORM 3 A) | I36: 1ST TERM | L36: 2ND TERM | P36: 3RD TERM
A37: NO. | B37: ADM | C37: NAME | E37: DEBT | H37: REPAYMENT
D38: ARREAS | E38: 2026 | H38: JAN | I38: FEB | J38: MAR | K38: APR | L38: MAY | M38: JUN | N38: JUL | O38: AUG | P38: SEP | Q38: OCT | R38: NOV | S38: PRE PAID | T38: BALANCE
B39: 1 | C39: BALANCE B/D | D39: =D31 | E39: =E31 | H39: =H31 | I39: =I31 | J39: =J31 | K39: =K31 | L39: =L31 | M39: =M31 | N39: =N31 | O39: =O31 | ... T39: =T31
A40: 28 | B40: 1793 | C40: STACY ADHIAMBO | D40: ='FORM 2 2025'!T40 | E40: 2200 | H40: 0 | T40: =D40+SUM(E40:G40)-SUM(H40:S40)
A41: 29 | B41: 1794 | C41: SCOVIAN AKINYI | D41: ='FORM 2 2025'!T41 | E41: 2200 | H41: 0 | T41: =D41+SUM(E41:G41)-SUM(H41:S41)
A42: 30 | B42: 1797 | C42: LUDY ATIENO | D42: ='FORM 2 2025'!T42 | E42: 2200 | P42: 750 | T42: =D42+SUM(E42:G42)-SUM(H42:S42)
A43: 31 | B43: 1802 | C43: STACY .A.OTUOMA | D43: ='FORM 2 2025'!T43 | E43: 2200 | H43: 0 | T43: =D43+SUM(E43:G43)-SUM(H43:S43)
...

Sheet FORM 4 2026
C1: KIREMBE SECONDARY SCHOOL.
C2: FEE REGISTER(LUNCH)2026 FORM 4 A | S2: 1ST TERM | V2: 2ND TERM | Z2: 3RD TERM
C3: NO. | D3: ADM | E3: NAME | G3: DEBT | R3: REPAYMENT
F4: ARREAS | G4: 2026 | R4: JAN | S4: FEB | T4: MAR | U4: APR | V4: MAY | W4: JUN | X4: JUL | Y4: AUG | Z4: SEP | AA4: OCT | AB4: NOV | AC4: PRE PAID | AD4: BALANCE
C5: 1 | D5: 1594 | E5: MARY ANYANGO | F5: 4200 | G5: 2200 | AD5: =F5+SUM(G5:Q5)-SUM(R5:AC5)
C6: 2 | D6: 1607 | E6: ELIZABETH ACHIENG | F6: 2200 | G6: 2200 | W6: 200 | AD6: =F6+SUM(G6:Q6)-SUM(R6:AC6)
C7: 3 | D7: 1608 | E7: MICHELLE .M.AKWARE | F7: 3200 | G7: 2200 | T7: 500 | W7: 1000 | AD7: =F7+SUM(G7:Q7)-SUM(R7:AC7)
C8: 4 | D8: 1610 | E8: BENEDETTE AWINO | F8: 3600 | G8: 2200 | AD8: =F8+SUM(G8:Q8)-SUM(R8:AC8)
C9: 5 | D9: 1613 | E9: IDA ADHIAMBO | F9: 1900 | G9: 2200 | W9: 1000 | AD9: =F9+SUM(G9:Q9)-SUM(R9:AC9)
C10: 6 | D10: 1614 | E10: MILLICENT .A. ONDU | F10: 650 | G10: 2200 | R10: 600 | S10: 450 | T10: 400 | U10: 780 | V10: 620 | AD10: =F10+SUM(G10:Q10)-SUM(R10:AC10)
C11: 7 | D11: 1618 | E11: YVONE ACHIENG | F11: 4200 | G11: 2200 | AD11: =F11+SUM(G11:Q11)-SUM(R11:AC11)
C12: 8 | D12: 1619 | E12: JANET ODANYA | F12: 2100 | G12: 2200 | AD12: =F12+SUM(G12:Q12)-SUM(R12:AC12)
C13: 9 | D13: 1622 | E13: PAULINE ADHIAMBO | F13: 1700 | G13: 2200 | AD13: =F13+SUM(G13:Q13)-SUM(R13:AC13)
C14: 10 | D14: 1623 | E14: EFFIE AWINO | F14: -800 | G14: 2200 | W14: 500 | AD14: =F14+SUM(G14:Q14)-SUM(R14:AC14)
C15: 11 | D15: 1626 | E15: MARCY ADHIAMBO | F15: 4400 | G15: 2200 | X15: 550 | AD15: =F15+SUM(G15:Q15)-SUM(R15:AC15)
C16: 12 | D16: 1628 | E16: ANN MICHELL OCHUKA | F16: -300 | G16: 2200 | R16: 500 | S16: 800 | T16: 100 | AD16: =F16+SUM(G16:Q16)-SUM(R16:AC16)
C17: 13 | D17: 1631 | E17: EVERLYNE ATIENO | F17: 3500 | G17: 2200 | AD17: =F17+SUM(G17:Q17)-SUM(R17:AC17)
C18: 14 | D18: 1642 | E18: FLORENCE ATIENO | F18: 1700 | G18: 2200 | AD18: =F18+SUM(G18:Q18)-SUM(R18:AC18)
C19: 15 | D19: 1643 | E19: JOYCE ATIENO | F19: 1600 | G19: 2200 | W19: 500 | AD19: =F19+SUM(G19:Q19)-SUM(R19:AC19)
C20: 16 | D20: 1644 | E20: ANNA ATIENO OTIENO | F20: 4200 | G20: 2200 | AD20: =F20+SUM(G20:Q20)-SUM(R20:AC20)
C21: 17 | D21: 1646 | E21: JULIAN ADONGO | F21: 800 | G21: 2200 | AD21: =F21+SUM(G21:Q21)-SUM(R21:AC21)
C22: 18 | D22: 1648 | E22: BECKY AKINYI | F22: 3850 | G22: 2200 | W22: 50 | AD22: =F22+SUM(G22:Q22)-SUM(R22:AC22)
C23: 19 | D23: 1649 | E23: VIVIAN AYAKO | F23: 600 | G23: 2200 | W23: 100 | AD23: =F23+SUM(G23:Q23)-SUM(R23:AC23)
C24: 20 | D24: 1654 | E24: MITCHEL AUMA | F24: 3450 | G24: 2200 | AD24: =F24+SUM(G24:Q24)-SUM(R24:AC24)
C25: 21 | D25: 1655 | E25: MILLICENT OCHUKA | F25: 3800 | G25: 2200 | W25: 200 | AD25: =F25+SUM(G25:Q25)-SUM(R25:AC25)
C26: 22 | D26: 1660 | E26: FAITH MARION | F26: 3250 | G26: 2200 | W26: 300 | AD26: =F26+SUM(G26:Q26)-SUM(R26:AC26)
C27: 23 | D27: 1661 | E27: LILIAN ADONGO | F27: 3150 | G27: 2200 | W27: 100 | AD27: =F27+SUM(G27:Q27)-SUM(R27:AC27)
C28: 24 | D28: 1662 | E28: MARCELINE AWUOR | F28: 4000 | G28: 2200 | W28: 300 | AD28: =F28+SUM(G28:Q28)-SUM(R28:AC28)
C29: 25 | D29: 1665 | E29: BRENDA AWUOR | F29: 2500 | G29: 2200 | W29: 800 | AD29: =F29+SUM(G29:Q29)-SUM(R29:AC29)
C30: 26 | D30: 1666 | E30: PAMELA AOKO | F30: 4200 | G30: 2200 | V30: 400 | AD30: =F30+SUM(G30:Q30)-SUM(R30:AC30)
E31: TOTAL | F31: =SUM(F5:F30) | G31: =SUM(G5:G30) | H31: =SUM(H5:H23) | I31: =SUM(I5:I23) | J31: =SUM(J5:J23) | K31: =SUM(K5:K23) | L31: =SUM(L5:L23) | M31: =SUM(M5:M23) | N31: =SUM(N5:N23) | O31: =SUM(O5:O23) | ... Q31: =SUM(Q5:Q23) | R31: =SUM(R5:R30) | S31: =SUM(S5:S30) | T31: =SUM(T5:T30) | U31: =SUM(U5:U30) | V31: =SUM(V5:V30) | W31: =SUM(W5:W30) | X31: =SUM(X5:X30) | Y31: =SUM(Y5:Y30) | ... AD31: =SUM(AD5:AD30)
C33: KIREMBE SECONDARY SCHOOL.
C34: FEE REGISTER(LUNCH)2026 FORM 4A | S34: 1ST TERM | V34: 2ND TERM | Z34: 3RD TERM
C35: NO. | D35: ADM | E35: NAME | G35: DEBT | R35: REPAYMENT
F36: ARREAS | G36: 2026 | R36: JAN | S36: FEB | T36: MAR | U36: APR | V36: MAY | W36: JUN | X36: JUL | Y36: AUG | Z36: SEP | AA36: OCT | AB36: NOV | AC36: PRE PAID | AD36: BALANCE
F37: =F31 | G37: =G31 | R37: =R31 | S37: =S31 | T37: =T31 | U37: =U31 | V37: =V31 | W37: =W31 | X37: =X31 | Y37: =Y31 | Z37: =Z31 | AC37: =AC31 | AD37: =AD31
C38: 27 | D38: 1667 | E38: PHILISTER ATIENO | F38: 2700 | G38: 2200 | AD38: =F38+SUM(G38:Q38)-SUM(R38:AC38)
C39: 28 | D39: 1668 | E39: REHEMA ACHIENG | F39: 3050 | G39: 2200 | R39: 1000 | S39: 1000 | AD39: =F39+SUM(G39:Q39)-SUM(R39:AC39)
C40: 29 | D40: 1672 | E40: MORREL AKINYI | F40: 4100 | G40: 2200 | AD40: =F40+SUM(G40:Q40)-SUM(R40:AC40)
C41: 30 | D41: 1676 | E41: CYNTHIA WEKESA | F41: 3050 | G41: 2200 | W41: 200 | AD41: =F41+SUM(G41:Q41)-SUM(R41:AC41)
...
